Workbook

Sheet Roadmap
A1: AMR Project Roadmap - แผนงานตั้งแต่ต้นจนจบ (Encoder/IMU calibration → Pilot)
A2: วิธีใช้: แก้เฉพาะคอลัมน์ 'สถานะ', 'ผู้รับผิดชอบ', 'ประมาณ (วัน)' (ตัวอักษรสีน้ำเงิน) ; Depends on 'n' = งานลำดับ n ใน phase เดียวกัน, 'Pk:n' = phase อื่น. ค่าประมาณวันเป็นการประเมินเบื้องต้นของผู้ช่วย ต้องปรับตามทีมจริง
A4: ID | B4: Phase | C4: งาน (Task) | D4: รายละเอียด / วิธีทำ | E4: เกณฑ์ผ่าน (Acceptance) | F4: เครื่องมือ / ไฟล์ | G4: Priority | H4: ต้องทำก่อน (Depends on) | I4: ประมาณ (วัน) | J4: สถานะ | K4: ผู้รับผิดชอบ | L4: Safety / หมายเหตุ
A5: P1-01 | B5: P1 Baseline & Encoder Odometry | C5: ตรวจ Hardware/Wiring ล้อ-มอเตอร์-Encoder-IMU-E-stop | D5: เช็คขั้วสาย, การยึด IMU (แกน Z ตั้งฉากพื้น, ยึดแน่น), ความตึงสายพาน/ล้อ, ความดันยาง/สภาพล้อ | E5: ทุกช่อง encoder นับได้ ไม่มี pulse หาย; IMU ไม่ขยับเมื่อจับเขย่า | F5: Multimeter, Foxglove | G5: สูง | I5: 0.5 | J5: เสร็จ | L5: เช็คก่อนทดสอบทุกครั้ง: E-stop ต้องตัดมอเตอร์ได้จริง
A6: P1-02 | B6: P1 Baseline & Encoder Odometry | C6: ยืนยัน ENCODER_PPR = 516.85 ทั้งสองล้อ | D6: ใช้ค่าจาก firmware เป็น ground truth (ไม่ใช้ LEFT_PPR/RIGHT_PPR ใน wheel_joint_state_publisher.py); หมุนล้อ 10 รอบด้วยมือนับ pulse | E6: pulse/รอบ คลาดเคลื่อน <0.5% | F6: stm/src/motor_control_with_pid_optimized.cpp | G6: สูง | H6: 1 | I6: 0.5 | J6: เสร็จ
A7: P1-03 | B7: P1 Baseline & Encoder Odometry | C7: Calibrate wheel_radius / ความเร็วเชิงเส้น (ซ้าย-ขวา แยกกัน) | D7: วิ่งตรง 5-10 m หลายรอบ วัดระยะจริง เทียบ odom (calib_straight_node.py) | E7: ระยะ error <1% และ drift ด้านข้าง <2 cm/5 m | F7: calib_straight_node.py, amr_calib_panel.py | G7: สูง | H7: 2 | I7: 1 | J7: ยังไม่เริ่ม
A8: P1-04 | B8: P1 Baseline & Encoder Odometry | C8: Calibrate wheel_sep (track width) ด้วยการหมุนอยู่กับที่ | D8: หมุน 360°/720° CW และ CCW ×5 รอบ วัดมุมจริงด้วยเส้นอ้างอิง/LiDAR; wheel_sep_true = nominal × commanded / actual | E8: มุมสะสม error <1° ต่อ 360°; CW กับ CCW ต่างกัน <1% | F8: calib_rotate_node.py | G8: สูง | H8: 3 | I8: 1 | J8: ยังไม่เริ่ม | L8: ทดสอบความเร็วต่ำ พื้นที่โล่ง ตรวจ E-stop ก่อน
A9: P1-05 | B9: P1 Baseline & Encoder Odometry | C9: Sync ค่า wheel_sep ทั้ง 4 ที่ (firmware, URDF, calib scripts, panel) | D9: แก้ 0.472 → ค่าใหม่ใน firmware, amr.urdf.xacro (wheel_separation), calib_rotate/straight_node, amr_calib_panel | E9: grep ไม่พบค่าเก่าเหลือ; build+flash ผ่าน | F9: git grep 0.472 | G9: สูง | H9: 4 | I9: 0.5 | J9: ยังไม่เริ่ม | L9: Flash firmware แล้วทดสอบความเร็วต่ำก่อนใช้งานจริง
A10: P1-06 | B10: P1 Baseline & Encoder Odometry | C10: ตรวจความแตกต่างซ้าย/ขวา (Motor table / PID) | D10: ทดสอบ step response ที่ 10-100% ตรวจ steady-state error และ overshoot; ต่อยอดจาก wheel_data และ calibration table V9.x | E10: error ความเร็วล้อ <3% ที่ทุกช่วง; ไม่ overshoot >10% | F10: wheel_data/, rosbag, PlotJuggler | G10: กลาง | H10: 5 | I10: 2 | J10: ยังไม่เริ่ม
A11: P2-01 | B11: P2 IMU Calibration | C11: เก็บ Gyro static noise/bias (นิ่ง 5-10 นาที) | D11: บันทึก /imu/data, คำนวณ bias, noise density, Allan variance (ถ้าทำได้); ตรวจอุณหภูมิ warm-up | E11: bias เสถียร; noise สอดคล้อง datasheet | F11: rosbag2, Python | G11: กลาง | H11: 1 | I11: 0.5 | J11: ยังไม่เริ่ม
A12: P2-02 | B12: P2 IMU Calibration | C12: Calibrate Gyro scale factor Z | D12: หมุนมุมรู้ค่า (360° ×5) เทียบมุมจริง; gyro_scale = actual/integrated แล้วใส่ใน publish_imu() | E12: scale error <0.5%; CW/CCW สมมาตร | F12: STM32 firmware, calib_rotate_node.py | G12: สูง | H12: P1:4 | I12: 1 | J12: ยังไม่เริ่ม
A13: P2-03 | B13: P2 IMU Calibration | C13: ตรวจ sign และแกน angular_velocity.z | D13: หมุน CCW ต้องเป็นค่าบวก (REP-103); ตรวจ frame_id ของ IMU ใน URDF | E13: หมุนซ้าย=+z ตรงกับ /wheel/odom | F13: ros2 topic echo | G13: สูง | H13: 2 | I13: 0.25 | J13: ยังไม่เริ่ม | L13: ตรวจก่อนเปิด EKF เสมอ (เคยพบอาการเลี้ยวผิดใน ekf.yaml)
A14: P2-04 | B14: P2 IMU Calibration | C14: ปรับ DLPF/sample rate และตรวจ vibration | D14: ทดสอบ DLPF ~20-42 Hz, ยึดฐาน IMU ให้แน่น/ใส่ damper; ตรวจ ZUPT ไม่ทำงานผิดตอนหมุน | E14: ความแกว่ง gyro ขณะหมุน steady <±3% | F14: firmware config, PlotJuggler | G14: กลาง | H14: 3 | I14: 1 | J14: ยังไม่เริ่ม
A15: P2-05 | B15: P2 IMU Calibration | C15: Calibrate accel (6-point) - ถ้าจะใช้งานจริง | D15: ทำเฉพาะเมื่อต้องใช้ ax/ay; ปกติไม่ fuse accel | E15: bias/scale accel ตรวจแล้ว | F15: - | G15: ต่ำ | H15: 1 | I15: 1 | J15: ยังไม่เริ่ม | L15: ทางเลือก
A16: P3-01 | B16: P3 Sensor Fusion (EKF) | C16: เปิด imu0 ใน ekf.yaml เฉพาะ vyaw | D16: แก้ imu0_config ให้ true เฉพาะ vyaw; ตั้ง covariance IMU และ /wheel/odom ตามค่า noise ที่วัดได้ | E16: EKF yaw ไม่ drift >2°/รอบ ที่ 360°×5 | F16: ekf.yaml, robot_localization | G16: สูง | H16: P2:3 | I16: 1 | J16: ยังไม่เริ่ม
A17: P3-02 | B17: P3 Sensor Fusion (EKF) | C17: ทดสอบ Odom: หมุน/สี่เหลี่ยม/วงกลม/กลับจุดเริ่ม (UMBmark) | D17: วิ่งสี่เหลี่ยม 2×2 m CW+CCW ×5 วัดตำแหน่งปลายทาง; ปรับ wheel_radius L/R และ wheel_sep | E17: error ตำแหน่งปลายทาง <5 cm, heading <2° | F17: calib_straight/circle_path_node.py | G17: สูง | H17: 1 | I17: 2 | J17: ยังไม่เริ่ม
A18: P3-03 | B18: P3 Sensor Fusion (EKF) | C18: Cross-check encoder vs IMU vs LiDAR (ดู slip) | D18: เพิ่ม node ตรวจ |w_enc - w_gyro| > threshold แล้ว flag ล้อลื่น/ชน | E18: ตรวจจับ slip ได้ในการทดสอบจงใจ | F18: Foxglove, ros2 node | G18: กลาง | H18: 2 | I18: 1 | J18: ยังไม่เริ่ม | L18: ใช้เป็น diagnostic ไม่ใช่ safety input
A19: P4-01 | B19: P4 SLAM & Mapping | C19: ตั้งค่า LiDAR (RPLIDAR C3) + laser_filters | D19: ตรวจ mount, TF (base_link→laser), blank-out มุมที่บังตัวรถ, ความถี่ scan | E19: ไม่มี self-hit; scan เสถียร ≥10 Hz | F19: laser_filters.yaml, Foxglove | G19: สูง | H19: P3:2 | I19: 1 | J19: ยังไม่เริ่ม
A20: P4-02 | B20: P4 SLAM & Mapping | C20: Extrinsic calibration LiDAR/Camera ใน URDF | D20: วัด offset ตำแหน่ง/มุม เทียบกับ base_footprint; ตรวจ TF tree | E20: กำแพงตรงเป็นเส้นตรงเมื่อหมุนรถ | F20: amr.urdf.xacro, RViz | G20: สูง | H20: 1 | I20: 1 | J20: ยังไม่เริ่ม
A21: P4-03 | B21: P4 SLAM & Mapping | C21: ทำแผนที่ (slam_toolbox) รอบโรงงาน | D21: Teleop ช้าๆ (<0.3 m/s), ปิด loop หลายจุด, หลีกเลี่ยงคน/ของเคลื่อนที่; บันทึก rosbag | E21: แผนที่ไม่เบี้ยว, loop closure ถูกต้อง | F21: slam_toolbox, rosboard, control panel | G21: สูง | H21: 2 | I21: 2 | J21: ยังไม่เริ่ม
A22: P4-04 | B22: P4 SLAM & Mapping | C22: ตัดแต่งแผนที่ + keepout/speed zones | D22: แก้ PGM ลบ noise; สร้าง keepout mask สำหรับโซน ESD/สายพาน/ทางเดินคน | E22: แผนที่สะอาด; keepout ทำงานใน Nav2 | F22: GIMP, nav2_map_server, keepout filter | G22: กลาง | H22: 3 | I22: 1 | J22: ยังไม่เริ่ม
A23: P5-01 | B23: P5 Localization & Navigation (Nav2/MPPI) | C23: ตั้งค่า AMCL/localization บนแผนที่ที่สร้าง | D23: ตั้ง initial pose, ทดสอบ kidnapped robot, ปรับ laser model | E23: pose error <10 cm/3° ในหลายจุด | F23: nav2_amcl, Foxglove | G23: สูง | H23: P4:4 | I23: 1 | J23: ยังไม่เริ่ม
A24: P5-02 | B24: P5 Localization & Navigation (Nav2/MPPI) | C24: Tune Costmap (footprint, inflation, obstacle layer + depth camera) | D24: ตั้ง footprint จริง, inflation ให้ผ่านทางแคบในโรงงาน, ใช้ HP60C ตรวจสิ่งกีดขวางต่ำ | E24: ผ่านประตู/ทางแคบตามที่กำหนดโดยไม่ชน | F24: nav2_params.yaml | G24: สูง | H24: 1 | I24: 2 | J24: ยังไม่เริ่ม | L24: เว้นระยะรอบรถตาม ISO 3691-4
A25: P5-03 | B25: P5 Localization & Navigation (Nav2/MPPI) | C25: Tune MPPI controller | D25: ปรับ vx_max, wz_max, critics weights, ความเร่ง/หน่วง ให้สอดคล้อง limit มอเตอร์ | E25: ไม่แกว่ง, เลี้ยวนุ่ม, ตามเส้นทาง error <10 cm | F25: nav2_params.yaml | G25: สูง | H25: 2 | I25: 3 | J25: ยังไม่เริ่ม
A26: P5-04 | B26: P5 Localization & Navigation (Nav2/MPPI) | C26: Tune Behavior Tree (recovery, retry, wait) | D26: ตั้ง recovery เมื่อถูกบล็อก, timeout, สั่งรอ/ถอย | E26: ไม่ค้าง ไม่วนไม่จบ; รายงานสถานะได้ | F26: behavior_trees/ | G26: กลาง | H26: 3 | I26: 2 | J26: ยังไม่เริ่ม
A27: P5-05 | B27: P5 Localization & Navigation (Nav2/MPPI) | C27: ทดสอบ Navigation ระยะยาว (multi-waypoint, 50+ รอบ) | D27: วิ่งเส้นทางจริงซ้ำ วัด success rate, เวลา, จำนวน recovery | E27: success ≥95% และไม่มีการชน | F27: rosbag, Foxglove | G27: สูง | H27: 4 | I27: 3 | J27: ยังไม่เริ่ม
A28: P6-01 | B28: P6 Safety & Compliance (ISO 3691-4) | C28: ระบุ Hazard/Risk Assessment (ISO 12100 / ISO 3691-4) | D28: ระบุอันตราย: ชนคน, ตกขอบ, ทับเท้า, Payload หล่น; กำหนด PL/SIL | E28: เอกสาร Risk Assessment อนุมัติ | F28: AMR_AGV_Safety_Checklist.xlsx | G28: สูง | I28: 2 | J28: ยังไม่เริ่ม | L28: หัวใจของมาตรฐาน
A29: P6-02 | B29: P6 Safety & Compliance (ISO 3691-4) | C29: E-stop ฮาร์ดแวร์ (ตัดพลังมอเตอร์ ไม่ผ่าน software) | D29: ติดตั้ง/ทดสอบวงจร E-stop, ปุ่มบนตัวรถ, ระยะหยุด | E29: ระยะหยุดตามที่คำนวณ; ตัดพลังได้ทุกกรณี | F29: Multimeter, ทดสอบ | G29: สูง | H29: 1 | I29: 2 | J29: ยังไม่เริ่ม | L29: ต้องเป็นวงจรอิสระจาก Jetson/ROS
A30: P6-03 | B30: P6 Safety & Compliance (ISO 3691-4) | C30: Safety LiDAR / Protective field / Bumper | D30: ตั้งโซน Stop/Slow ตามความเร็วและระยะเบรก; ทดสอบวัตถุมาตรฐาน | E30: ตรวจจับคน/ขาที่ระยะที่กำหนด | F30: Safety scanner/bumper | G30: สูง | H30: 1 | I30: 3 | J30: ยังไม่เริ่ม | L30: RPLIDAR C3 ไม่ใช่ safety-rated
A31: P6-04 | B31: P6 Safety & Compliance (ISO 3691-4) | C31: ตัวบ่งชี้เตือน (ไฟ/เสียง) + จำกัดความเร็วตามโซน | D31: ไฟสถานะ, buzzer ตอนถอย/เลี้ยว, ความเร็ว ≤ ตามพื้นที่คนเดิน | E31: ทดสอบผ่านตาม checklist | F31: - | G31: กลาง | H31: 2 | I31: 1 | J31: ยังไม่เริ่ม
A32: P6-05 | B32: P6 Safety & Compliance (ISO 3691-4) | C32: Watchdog / Fail-safe (micro-ROS ขาด, cmd_vel timeout) | D32: STM32 หยุดมอเตอร์เมื่อไม่มีคำสั่ง >X ms; ตรวจ Jetson ค้าง/สาย USB หลุด | E32: หยุดภายใน timeout ทุกกรณีทดสอบ | F32: firmware, micro-ROS agent | G32: สูง | I32: 2 | J32: ยังไม่เริ่ม
A33: P6-06 | B33: P6 Safety & Compliance (ISO 3691-4) | C33: ทดสอบ Safety functions และบันทึกผล | D33: ทำตาม checklist, เก็บหลักฐาน/รูป/วิดีโอ | E33: ทุกข้อ pass ก่อนใช้กับคน | F33: AMR_AGV_Safety_Checklist.xlsx | G33: สูง | H33: 2,3,4,5 | I33: 2 | J33: ยังไม่เริ่ม | L33: ห้ามใช้งานใกล้คนก่อนผ่านข้อนี้
A34: P7-01 | B34: P7 System Integration & Operations | C34: Bringup อัตโนมัติ (systemd/launch) + Watchdog Jetson | D34: auto-start ROS2 stack, restart เมื่อ crash, ตรวจ power mode/temperature | E34: เปิดเครื่องแล้วพร้อมใช้ ≤ 2 นาที | F34: systemd, bringup.launch.py | G34: กลาง | H34: P5:5 | I34: 1 | J34: ยังไม่เริ่ม
A35: P7-02 | B35: P7 System Integration & Operations | C35: Control panel / Foxglove dashboard สำหรับ Operator | D35: ปุ่ม Start/Stop, เลือกเส้นทาง, แสดงแบตเตอรี่/ข้อผิดพลาด (ภาษาไทย) | E35: operator ใช้ได้โดยไม่ต้องใช้ terminal | F35: amr_control_panel.py | G35: กลาง | H35: 1 | I35: 2 | J35: ยังไม่เริ่ม | L35: ผู้ใช้คือ operator ไลน์ PCB
A36: P7-03 | B36: P7 System Integration & Operations | C36: Mission/Station: Docking / Payload / Handover | D36: กำหนด station (SMT, AOI, Warehouse), การจอดเข้าจุดแม่นยำ, ตรวจ Payload | E36: จอดคลาดเคลื่อน <2 cm (หรือตามงาน) | F36: Nav2 docking, AprilTag/reflector | G36: กลาง | H36: 1 | I36: 4 | J36: ยังไม่เริ่ม | L36: ตรวจ ESD ของ Payload/ล้อ
A37: P7-04 | B37: P7 System Integration & Operations | C37: Battery/Charging management | D37: อ่านแรงดัน/SoC, ขีดจำกัดต่ำ→กลับ charge, ทดสอบ discharge curve | E37: ไม่ดับกลางทาง; กลับจุดชาร์จอัตโนมัติ | F37: STM32 ADC, BMS | G37: กลาง | I37: 2 | J37: ยังไม่เริ่ม
A38: P7-05 | B38: P7 System Integration & Operations | C38: Logging / Diagnostics / Remote monitoring | D38: บันทึก rosbag เหตุผิดปกติ, health topic, Foxglove remote | E38: ย้อนดูเหตุการณ์ได้ | F38: rosbag2, diagnostics | G38: กลาง | H38: 1 | I38: 1 | J38: ยังไม่เริ่ม
A39: P7-06 | B39: P7 System Integration & Operations | C39: Fleet Management (ถ้ามีหลายคัน) | D39: ทำ traffic management, job queue, MQTT/Open-RMF | E39: 2+ คันไม่ชน/ไม่ deadlock | F39: Open-RMF | G39: ต่ำ | I39: 5 | J39: ยังไม่เริ่ม | L39: ทางเลือกระยะถัดไป
A40: P8-01 | B40: P8 Pilot, Documentation & Handover | C40: Pilot run ในไลน์จริง (1-2 สัปดาห์) | D40: ให้ operator ใช้งานจริง บันทึกปัญหา/ MTBF/ success rate | E40: ≥95% mission success, ไม่มี safety incident | F40: Log, checklist | G40: สูง | H40: P6:6,P7:1 | I40: 10 | J40: ยังไม่เริ่ม
A41: P8-02 | B41: P8 Pilot, Documentation & Handover | C41: เอกสาร: คู่มือ Operator + Maintenance + SOP ฉุกเฉิน | D41: ขั้นตอนเปิด/ปิด, ชาร์จ, ล้างแผนที่, การตรวจประจำวัน, แก้ปัญหาเบื้องต้น | E41: ผู้อื่นทำตามเอกสารได้เอง | F41: document/ | G41: กลาง | H41: 1 | I41: 3 | J41: ยังไม่เริ่ม
...

Sheet Summary
A1: สรุปความคืบหน้าตาม Phase (คำนวณอัตโนมัติจากชีต Roadmap)
A3: Phase | B3: จำนวนงาน | C3: เสร็จ | D3: กำลังทำ | E3: ติดปัญหา | F3: % เสร็จ | G3: วันรวม (ประมาณ) | H3: วันคงเหลือ
A4: P1 Baseline & Encoder Odometry | B4: =COUNTIF(Roadmap!$B$5:$B$43,A4) -> 6 | C4: =COUNTIFS(Roadmap!$B$5:$B$43,A4,Roadmap!$J$5:$J$43,"เสร็จ") -> 2 | D4: =COUNTIFS(Roadmap!$B$5:$B$43,A4,Roadmap!$J$5:$J$43,"กำลังทำ") -> 0 | E4: =COUNTIFS(Roadmap!$B$5:$B$43,A4,Roadmap!$J$5:$J$43,"ติดปัญหา") -> 0 | F4: =IF(B4=0,0,C4/B4) -> 0.33333333 | G4: =SUMIFS(Roadmap!$I$5:$I$43,Roadmap!$B$5:$B$43,A4) -> 5.5 | H4: =G4-SUMIFS(Roadmap!$I$5:$I$43,Roadmap!$B$5:$B$43,A4,Roadmap!$J$5:$J$43,"เสร็จ") -> 4.5
A5: P2 IMU Calibration | B5: =COUNTIF(Roadmap!$B$5:$B$43,A5) -> 5 | C5: =COUNTIFS(Roadmap!$B$5:$B$43,A5,Roadmap!$J$5:$J$43,"เสร็จ") -> 0 | D5: =COUNTIFS(Roadmap!$B$5:$B$43,A5,Roadmap!$J$5:$J$43,"กำลังทำ") -> 0 | E5: =COUNTIFS(Roadmap!$B$5:$B$43,A5,Roadmap!$J$5:$J$43,"ติดปัญหา") -> 0 | F5: =IF(B5=0,0,C5/B5) -> 0 | G5: =SUMIFS(Roadmap!$I$5:$I$43,Roadmap!$B$5:$B$43,A5) -> 3.75 | H5: =G5-SUMIFS(Roadmap!$I$5:$I$43,Roadmap!$B$5:$B$43,A5,Roadmap!$J$5:$J$43,"เสร็จ") -> 3.75
A6: P3 Sensor Fusion (EKF) | B6: =COUNTIF(Roadmap!$B$5:$B$43,A6) -> 3 | C6: =COUNTIFS(Roadmap!$B$5:$B$43,A6,Roadmap!$J$5:$J$43,"เสร็จ") -> 0 | D6: =COUNTIFS(Roadmap!$B$5:$B$43,A6,Roadmap!$J$5:$J$43,"กำลังทำ") -> 0 | E6: =COUNTIFS(Roadmap!$B$5:$B$43,A6,Roadmap!$J$5:$J$43,"ติดปัญหา") -> 0 | F6: =IF(B6=0,0,C6/B6) -> 0 | G6: =SUMIFS(Roadmap!$I$5:$I$43,Roadmap!$B$5:$B$43,A6) -> 4 | H6: =G6-SUMIFS(Roadmap!$I$5:$I$43,Roadmap!$B$5:$B$43,A6,Roadmap!$J$5:$J$43,"เสร็จ") -> 4
A7: P4 SLAM & Mapping | B7: =COUNTIF(Roadmap!$B$5:$B$43,A7) -> 4 | C7: =COUNTIFS(Roadmap!$B$5:$B$43,A7,Roadmap!$J$5:$J$43,"เสร็จ") -> 0 | D7: =COUNTIFS(Roadmap!$B$5:$B$43,A7,Roadmap!$J$5:$J$43,"กำลังทำ") -> 0 | E7: =COUNTIFS(Roadmap!$B$5:$B$43,A7,Roadmap!$J$5:$J$43,"ติดปัญหา") -> 0 | F7: =IF(B7=0,0,C7/B7) -> 0 | G7: =SUMIFS(Roadmap!$I$5:$I$43,Roadmap!$B$5:$B$43,A7) -> 5 | H7: =G7-SUMIFS(Roadmap!$I$5:$I$43,Roadmap!$B$5:$B$43,A7,Roadmap!$J$5:$J$43,"เสร็จ") -> 5
A8: P5 Localization & Navigation (Nav2/MPPI) | B8: =COUNTIF(Roadmap!$B$5:$B$43,A8) -> 5 | C8: =COUNTIFS(Roadmap!$B$5:$B$43,A8,Roadmap!$J$5:$J$43,"เสร็จ") -> 0 | D8: =COUNTIFS(Roadmap!$B$5:$B$43,A8,Roadmap!$J$5:$J$43,"กำลังทำ") -> 0 | E8: =COUNTIFS(Roadmap!$B$5:$B$43,A8,Roadmap!$J$5:$J$43,"ติดปัญหา") -> 0 | F8: =IF(B8=0,0,C8/B8) -> 0 | G8: =SUMIFS(Roadmap!$I$5:$I$43,Roadmap!$B$5:$B$43,A8) -> 11 | H8: =G8-SUMIFS(Roadmap!$I$5:$I$43,Roadmap!$B$5:$B$43,A8,Roadmap!$J$5:$J$43,"เสร็จ") -> 11
A9: P6 Safety & Compliance (ISO 3691-4) | B9: =COUNTIF(Roadmap!$B$5:$B$43,A9) -> 6 | C9: =COUNTIFS(Roadmap!$B$5:$B$43,A9,Roadmap!$J$5:$J$43,"เสร็จ") -> 0 | D9: =COUNTIFS(Roadmap!$B$5:$B$43,A9,Roadmap!$J$5:$J$43,"กำลังทำ") -> 0 | E9: =COUNTIFS(Roadmap!$B$5:$B$43,A9,Roadmap!$J$5:$J$43,"ติดปัญหา") -> 0 | F9: =IF(B9=0,0,C9/B9) -> 0 | G9: =SUMIFS(Roadmap!$I$5:$I$43,Roadmap!$B$5:$B$43,A9) -> 12 | H9: =G9-SUMIFS(Roadmap!$I$5:$I$43,Roadmap!$B$5:$B$43,A9,Roadmap!$J$5:$J$43,"เสร็จ") -> 12
A10: P7 System Integration & Operations | B10: =COUNTIF(Roadmap!$B$5:$B$43,A10) -> 6 | C10: =COUNTIFS(Roadmap!$B$5:$B$43,A10,Roadmap!$J$5:$J$43,"เสร็จ") -> 0 | D10: =COUNTIFS(Roadmap!$B$5:$B$43,A10,Roadmap!$J$5:$J$43,"กำลังทำ") -> 0 | E10: =COUNTIFS(Roadmap!$B$5:$B$43,A10,Roadmap!$J$5:$J$43,"ติดปัญหา") -> 0 | F10: =IF(B10=0,0,C10/B10) -> 0 | G10: =SUMIFS(Roadmap!$I$5:$I$43,Roadmap!$B$5:$B$43,A10) -> 15 | H10: =G10-SUMIFS(Roadmap!$I$5:$I$43,Roadmap!$B$5:$B$43,A10,Roadmap!$J$5:$J$43,"เสร็จ") -> 15
A11: P8 Pilot, Documentation & Handover | B11: =COUNTIF(Roadmap!$B$5:$B$43,A11) -> 4 | C11: =COUNTIFS(Roadmap!$B$5:$B$43,A11,Roadmap!$J$5:$J$43,"เสร็จ") -> 0 | D11: =COUNTIFS(Roadmap!$B$5:$B$43,A11,Roadmap!$J$5:$J$43,"กำลังทำ") -> 0 | E11: =COUNTIFS(Roadmap!$B$5:$B$43,A11,Roadmap!$J$5:$J$43,"ติดปัญหา") -> 0 | F11: =IF(B11=0,0,C11/B11) -> 0 | G11: =SUMIFS(Roadmap!$I$5:$I$43,Roadmap!$B$5:$B$43,A11) -> 15 | H11: =G11-SUMIFS(Roadmap!$I$5:$I$43,Roadmap!$B$5:$B$43,A11,Roadmap!$J$5:$J$43,"เสร็จ") -> 15
A12: รวมทั้งหมด | B12: =SUM(B4:B11) -> 39 | C12: =SUM(C4:C11) -> 2 | D12: =SUM(D4:D11) -> 0 | E12: =SUM(E4:E11) -> 0 | F12: =IF(B12=0,0,C12/B12) -> 0.051282051 | G12: =SUM(G4:G11) -> 71.25 | H12: =SUM(H4:H11) -> 70.25
A14: หมายเหตุ:
A15: - ค่า 'ประมาณ (วัน)' เป็นการประเมินเบื้องต้นโดยผู้ช่วย ไม่ใช่ข้อมูลจากทีม ให้ปรับตามกำลังคนจริง (วันรวมเป็น man-day ต่อเนื่อง ไม่ได้ทำขนานกัน)
A16: - ลำดับแนะนำ: P1 → P2 → P3 → P4 → P5 ; P6 (Safety) ทำขนานตั้งแต่ต้นและต้องผ่านก่อน Pilot ใน P8
A17: - งานสำคัญทันที (ต่อจากผลทดสอบล่าสุด): P1-04 wheel_sep, P2-02 gyro scale, P2-03 ตรวจ sign, P3-01 เปิด IMU ใน EKF
